[2023-12-03 17:03:59,995] ERROR log_exception() L825  Exception on /doce [POST] - call_trace=/usr/local/lib/python3.10/dist-packages/flask/app.py L825 
Traceback (most recent call last):
  File "/usr/local/lib/python3.10/dist-packages/flask/app.py", line 1455, in wsgi_app
    response = self.full_dispatch_request()
  File "/usr/local/lib/python3.10/dist-packages/flask/app.py", line 869, in full_dispatch_request
    rv = self.handle_user_exception(e)
  File "/usr/local/lib/python3.10/dist-packages/flask_cors/extension.py", line 176, in wrapped_function
    return cors_after_request(app.make_response(f(*args, **kwargs)))
  File "/usr/local/lib/python3.10/dist-packages/flask/app.py", line 867, in full_dispatch_request
    rv = self.dispatch_request()
  File "/usr/local/lib/python3.10/dist-packages/flask/app.py", line 852, in dispatch_request
    return self.ensure_sync(self.view_functions[rule.endpoint])(**view_args)
  File "/usr/local/lib/python3.10/dist-packages/flask_openapi3/scaffold.py", line 117, in view_func
    response = func(**func_kwargs)
  File "/workspaces/Api_confeitaria_backend-master/app.py", line 56, in add_doce
    imagem_path = os.path.join(app.config['UPLOAD_FOLDER'], filename)
NameError: name 'filename' is not defined
[2023-12-03 17:04:00,092] INFO _log() L96   127.0.0.1 - - [03/Dec/2023 17:04:00] "[35m[1mPOST /doce HTTP/1.1[0m" 500 - - call_trace=/usr/local/lib/python3.10/dist-packages/werkzeug/_internal.py L96  
[2023-12-03 17:04:10,337] INFO _log() L96   [31m[1mWARNING: This is a development server. Do not use it in a production deployment. Use a production WSGI server instead.[0m
 * Running on all addresses (0.0.0.0)
 * Running on http://127.0.0.1:5000
 * Running on http://172.17.0.2:5000 - call_trace=/usr/local/lib/python3.10/dist-packages/werkzeug/_internal.py L96  
[2023-12-03 17:04:10,348] INFO _log() L96   [33mPress CTRL+C to quit[0m - call_trace=/usr/local/lib/python3.10/dist-packages/werkzeug/_internal.py L96  
[2023-12-03 17:04:12,536] INFO _log() L96   127.0.0.1 - - [03/Dec/2023 17:04:12] "[31m[1mPOST /doce HTTP/1.1[0m" 409 - - call_trace=/usr/local/lib/python3.10/dist-packages/werkzeug/_internal.py L96  
[2023-12-03 17:04:41,016] INFO _log() L96   [31m[1mWARNING: This is a development server. Do not use it in a production deployment. Use a production WSGI server instead.[0m
 * Running on all addresses (0.0.0.0)
 * Running on http://127.0.0.1:5000
 * Running on http://172.17.0.2:5000 - call_trace=/usr/local/lib/python3.10/dist-packages/werkzeug/_internal.py L96  
[2023-12-03 17:04:41,023] INFO _log() L96   [33mPress CTRL+C to quit[0m - call_trace=/usr/local/lib/python3.10/dist-packages/werkzeug/_internal.py L96  
[2023-12-03 17:04:49,757] INFO _log() L96   127.0.0.1 - - [03/Dec/2023 17:04:49] "[33mGET /images/F_UTD4xWYAAdStq.jpg HTTP/1.1[0m" 404 - - call_trace=/usr/local/lib/python3.10/dist-packages/werkzeug/_internal.py L96  
[2023-12-03 17:04:49,902] INFO _log() L96   127.0.0.1 - - [03/Dec/2023 17:04:49] "[33mGET /favicon.ico HTTP/1.1[0m" 404 - - call_trace=/usr/local/lib/python3.10/dist-packages/werkzeug/_internal.py L96  
[2023-12-03 17:05:54,408] INFO _log() L96   [31m[1mWARNING: This is a development server. Do not use it in a production deployment. Use a production WSGI server instead.[0m
 * Running on all addresses (0.0.0.0)
 * Running on http://127.0.0.1:5000
 * Running on http://172.17.0.2:5000 - call_trace=/usr/local/lib/python3.10/dist-packages/werkzeug/_internal.py L96  
[2023-12-03 17:05:54,415] INFO _log() L96   [33mPress CTRL+C to quit[0m - call_trace=/usr/local/lib/python3.10/dist-packages/werkzeug/_internal.py L96  
[2023-12-03 17:05:56,398] ERROR log_exception() L825  Exception on /images/F_UTD4xWYAAdStq.jpg [GET] - call_trace=/usr/local/lib/python3.10/dist-packages/flask/app.py L825 
Traceback (most recent call last):
  File "/usr/local/lib/python3.10/dist-packages/flask/app.py", line 1455, in wsgi_app
    response = self.full_dispatch_request()
  File "/usr/local/lib/python3.10/dist-packages/flask/app.py", line 869, in full_dispatch_request
    rv = self.handle_user_exception(e)
  File "/usr/local/lib/python3.10/dist-packages/flask_cors/extension.py", line 176, in wrapped_function
    return cors_after_request(app.make_response(f(*args, **kwargs)))
  File "/usr/local/lib/python3.10/dist-packages/flask/app.py", line 867, in full_dispatch_request
    rv = self.dispatch_request()
  File "/usr/local/lib/python3.10/dist-packages/flask/app.py", line 852, in dispatch_request
    return self.ensure_sync(self.view_functions[rule.endpoint])(**view_args)
  File "/workspaces/Api_confeitaria_backend-master/app.py", line 35, in uploaded_file
    return send_from_directory(app.config['UPLOAD_FOLDER'], filename)
NameError: name 'send_from_directory' is not defined
[2023-12-03 17:05:56,405] INFO _log() L96   127.0.0.1 - - [03/Dec/2023 17:05:56] "[35m[1mGET /images/F_UTD4xWYAAdStq.jpg HTTP/1.1[0m" 500 - - call_trace=/usr/local/lib/python3.10/dist-packages/werkzeug/_internal.py L96  
[2023-12-03 17:06:28,442] INFO _log() L96   [31m[1mWARNING: This is a development server. Do not use it in a production deployment. Use a production WSGI server instead.[0m
 * Running on all addresses (0.0.0.0)
 * Running on http://127.0.0.1:5000
 * Running on http://172.17.0.2:5000 - call_trace=/usr/local/lib/python3.10/dist-packages/werkzeug/_internal.py L96  
[2023-12-03 17:06:28,453] INFO _log() L96   [33mPress CTRL+C to quit[0m - call_trace=/usr/local/lib/python3.10/dist-packages/werkzeug/_internal.py L96  
[2023-12-03 17:06:30,365] INFO _log() L96   127.0.0.1 - - [03/Dec/2023 17:06:30] "GET /images/F_UTD4xWYAAdStq.jpg HTTP/1.1" 200 - - call_trace=/usr/local/lib/python3.10/dist-packages/werkzeug/_internal.py L96  
[2023-12-03 17:08:18,126] INFO _log() L96   [31m[1mWARNING: This is a development server. Do not use it in a production deployment. Use a production WSGI server instead.[0m
 * Running on all addresses (0.0.0.0)
 * Running on http://127.0.0.1:5000
 * Running on http://172.17.0.2:5000 - call_trace=/usr/local/lib/python3.10/dist-packages/werkzeug/_internal.py L96  
[2023-12-03 17:08:18,133] INFO _log() L96   [33mPress CTRL+C to quit[0m - call_trace=/usr/local/lib/python3.10/dist-packages/werkzeug/_internal.py L96  
[2023-12-03 17:08:25,893] WARNING add_doce() L88   Erro ao adicionar doce 'dushaudhasudh', N√£o foi poss√≠vel salvar novo doce :/ - call_trace=/workspaces/Api_confeitaria_backend-master/app.py L88  
[2023-12-03 17:08:25,896] INFO _log() L96   127.0.0.1 - - [03/Dec/2023 17:08:25] "[31m[1mPOST /doce HTTP/1.1[0m" 400 - - call_trace=/usr/local/lib/python3.10/dist-packages/werkzeug/_internal.py L96  
[2023-12-03 17:09:16,706] INFO _log() L96   [31m[1mWARNING: This is a development server. Do not use it in a production deployment. Use a production WSGI server instead.[0m
 * Running on all addresses (0.0.0.0)
 * Running on http://127.0.0.1:5000
 * Running on http://172.17.0.2:5000 - call_trace=/usr/local/lib/python3.10/dist-packages/werkzeug/_internal.py L96  
[2023-12-03 17:09:16,713] INFO _log() L96   [33mPress CTRL+C to quit[0m - call_trace=/usr/local/lib/python3.10/dist-packages/werkzeug/_internal.py L96  
[2023-12-03 17:09:18,494] WARNING add_doce() L88   Erro ao adicionar doce 'dushaudhasudh', N√£o foi poss√≠vel salvar novo doce :/ - call_trace=/workspaces/Api_confeitaria_backend-master/app.py L88  
[2023-12-03 17:09:18,497] INFO _log() L96   127.0.0.1 - - [03/Dec/2023 17:09:18] "[31m[1mPOST /doce HTTP/1.1[0m" 400 - - call_trace=/usr/local/lib/python3.10/dist-packages/werkzeug/_internal.py L96  
[2023-12-03 17:10:35,452] INFO _log() L96   [31m[1mWARNING: This is a development server. Do not use it in a production deployment. Use a production WSGI server instead.[0m
 * Running on all addresses (0.0.0.0)
 * Running on http://127.0.0.1:5000
 * Running on http://172.17.0.2:5000 - call_trace=/usr/local/lib/python3.10/dist-packages/werkzeug/_internal.py L96  
[2023-12-03 17:10:35,459] INFO _log() L96   [33mPress CTRL+C to quit[0m - call_trace=/usr/local/lib/python3.10/dist-packages/werkzeug/_internal.py L96  
[2023-12-03 17:11:39,916] WARNING add_doce() L88   Erro ao adicionar doce 'dushaudhasudh', N√£o foi poss√≠vel salvar novo doce :/ - call_trace=/workspaces/Api_confeitaria_backend-master/app.py L88  
[2023-12-03 17:11:39,918] INFO _log() L96   127.0.0.1 - - [03/Dec/2023 17:11:39] "[31m[1mPOST /doce HTTP/1.1[0m" 400 - - call_trace=/usr/local/lib/python3.10/dist-packages/werkzeug/_internal.py L96  
[2023-12-03 17:11:46,959] INFO _log() L96   [31m[1mWARNING: This is a development server. Do not use it in a production deployment. Use a production WSGI server instead.[0m
 * Running on all addresses (0.0.0.0)
 * Running on http://127.0.0.1:5000
 * Running on http://172.17.0.2:5000 - call_trace=/usr/local/lib/python3.10/dist-packages/werkzeug/_internal.py L96  
[2023-12-03 17:11:46,966] INFO _log() L96   [33mPress CTRL+C to quit[0m - call_trace=/usr/local/lib/python3.10/dist-packages/werkzeug/_internal.py L96  
[2023-12-03 17:11:49,446] INFO _log() L96   127.0.0.1 - - [03/Dec/2023 17:11:49] "[31m[1mPOST /doce HTTP/1.1[0m" 409 - - call_trace=/usr/local/lib/python3.10/dist-packages/werkzeug/_internal.py L96  
[2023-12-03 17:12:08,082] INFO _log() L96   [31m[1mWARNING: This is a development server. Do not use it in a production deployment. Use a production WSGI server instead.[0m
 * Running on all addresses (0.0.0.0)
 * Running on http://127.0.0.1:5000
 * Running on http://172.17.0.2:5000 - call_trace=/usr/local/lib/python3.10/dist-packages/werkzeug/_internal.py L96  
[2023-12-03 17:12:08,089] INFO _log() L96   [33mPress CTRL+C to quit[0m - call_trace=/usr/local/lib/python3.10/dist-packages/werkzeug/_internal.py L96  
[2023-12-03 17:12:12,288] INFO _log() L96   127.0.0.1 - - [03/Dec/2023 17:12:12] "[31m[1mPOST /doce HTTP/1.1[0m" 409 - - call_trace=/usr/local/lib/python3.10/dist-packages/werkzeug/_internal.py L96  
